<?xml version="1.0" encoding="utf-8"?>
<!-- This URDF was automatically created by SolidWorks to URDF Exporter! Originally created by Stephen Brawner (brawner@gmail.com) 
     Commit Version: 1.6.0-4-g7f85cfe  Build Version: 1.6.7995.38578
     For more information, please see http://wiki.ros.org/sw_urdf_exporter -->
<robot
  name="model_config">
  <link
    name="base_link">
    <inertial>
      <origin
        xyz="-0.00139951535596307 -0.000115543065105189 0.0216761359378849"
        rpy="0 0 0" />
      <mass
        value="0.230625387437769" />
      <inertia
        ixx="0.000397638701759869"
        ixy="3.72485292325441E-08"
        ixz="3.95689083442152E-07"
        iyy="0.000377909155069588"
        iyz="1.14903758060562E-06"
        izz="0.000669921803810015" />
    </inertial>
    <visual>
      <origin
        xyz="0 0 0"
        rpy="0 0 0" />
      <geometry>
        <mesh
          filename="package://model_config/meshes/base_link.STL" />
      </geometry>
      <material
        name="">
        <color
          rgba="1 1 1 1" />
      </material>
    </visual>
    <collision>
      <origin
        xyz="0 0 0"
        rpy="0 0 0" />
      <geometry>
        <mesh
          filename="package://model_config/meshes/base_link.STL" />
      </geometry>
    </collision>
  </link>
  <link
    name="Link1">
    <inertial>
      <origin
        xyz="1.50784939704832E-05 0.00589355602458163 -0.00742072785825368"
        rpy="0 0 0" />
      <mass
        value="1.0672662124327" />
      <inertia
        ixx="0.00213823053280256"
        ixy="7.89344919991784E-07"
        ixz="-6.64292075174937E-07"
        iyy="0.00203272365399182"
        iyz="-5.72905036059312E-05"
        izz="0.00203864730057834" />
    </inertial>
    <visual>
      <origin
        xyz="0 0 0"
        rpy="0 0 0" />
      <geometry>
        <mesh
          filename="package://model_config/meshes/Link1.STL" />
      </geometry>
      <material
        name="">
        <color
          rgba="1 1 1 1" />
      </material>
    </visual>
    <collision>
      <origin
        xyz="0 0 0"
        rpy="0 0 0" />
      <geometry>
        <mesh
          filename="package://model_config/meshes/Link1.STL" />
      </geometry>
    </collision>
  </link>
  <joint
    name="Joint1"
    type="revolute">
    <origin
      xyz="0 0 0.1123"
      rpy="0 0 -3.1416" />
    <parent
      link="base_link" />
    <child
      link="Link1" />
    <axis
      xyz="0 0 1" />
    <limit
      lower="-3.14"
      upper="3.14"
      effort="100"
      velocity="1" />
  </joint>
  <link
    name="Link2">
    <inertial>
      <origin
        xyz="0.22533540270956 -1.31661100304076E-06 0.0380381442934632"
        rpy="0 0 0" />
      <mass
        value="2.85311721697769" />
      <inertia
        ixx="0.00522538010252365"
        ixy="-1.56998766397489E-06"
        ixz="-1.65659439430173E-07"
        iyy="0.00998453368426239"
        iyz="1.41752496270541E-07"
        izz="0.00994260642816178" />
    </inertial>
    <visual>
      <origin
        xyz="0 0 0"
        rpy="0 0 0" />
      <geometry>
        <mesh
          filename="package://model_config/meshes/Link2.STL" />
      </geometry>
      <material
        name="">
        <color
          rgba="1 1 1 1" />
      </material>
    </visual>
    <collision>
      <origin
        xyz="0 0 0"
        rpy="0 0 0" />
      <geometry>
        <mesh
          filename="package://model_config/meshes/Link2.STL" />
      </geometry>
    </collision>
  </link>
  <joint
    name="Joint2"
    type="revolute">
    <origin
      xyz="0 0.0856 0"
      rpy="1.5708 -1.5708 0" />
    <parent
      link="Link1" />
    <child
      link="Link2" />
    <axis
      xyz="0 0 1" />
    <limit
      lower="-3.14"
      upper="3.14"
      effort="100"
      velocity="1" />
  </joint>
  <link
    name="Link3">
    <inertial>
      <origin
        xyz="0.139148144215519 -6.87999984808206E-06 0.0888783999044399"
        rpy="0 0 0" />
      <mass
        value="1.52858398755293" />
      <inertia
        ixx="0.00207337440937713"
        ixy="-5.88009463390305E-07"
        ixz="2.38936156173591E-05"
        iyy="0.0061006269762059"
        iyz="3.44375753542566E-07"
        izz="0.00646696736900643" />
    </inertial>
    <visual>
      <origin
        xyz="0 0 0"
        rpy="0 0 0" />
      <geometry>
        <mesh
          filename="package://model_config/meshes/Link3.STL" />
      </geometry>
      <material
        name="">
        <color
          rgba="1 1 1 1" />
      </material>
    </visual>
    <collision>
      <origin
        xyz="0 0 0"
        rpy="0 0 0" />
      <geometry>
        <mesh
          filename="package://model_config/meshes/Link3.STL" />
      </geometry>
    </collision>
  </link>
  <joint
    name="Joint3"
    type="revolute">
    <origin
      xyz="0.425 0 0"
      rpy="3.1416 0 0" />
    <parent
      link="Link2" />
    <child
      link="Link3" />
    <axis
      xyz="0 0 1" />
    <limit
      lower="-3.14"
      upper="3.14"
      effort="100"
      velocity="1" />
  </joint>
  <link
    name="Link4">
    <inertial>
      <origin
        xyz="-8.32234892130002E-06 0.00157877686994723 -0.00388134555762737"
        rpy="0 0 0" />
      <mass
        value="0.300359691421369" />
      <inertia
        ixx="0.000245139698341275"
        ixy="-7.26850730917096E-08"
        ixz="-2.01057423987851E-08"
        iyy="0.000255934527275935"
        iyz="-4.80810300910988E-07"
        izz="0.000230422587893387" />
    </inertial>
    <visual>
      <origin
        xyz="0 0 0"
        rpy="0 0 0" />
      <geometry>
        <mesh
          filename="package://model_config/meshes/Link4.STL" />
      </geometry>
      <material
        name="">
        <color
          rgba="1 1 1 1" />
      </material>
    </visual>
    <collision>
      <origin
        xyz="0 0 0"
        rpy="0 0 0" />
      <geometry>
        <mesh
          filename="package://model_config/meshes/Link4.STL" />
      </geometry>
    </collision>
  </link>
  <joint
    name="Joint4"
    type="revolute">
    <origin
      xyz="0.401 0 0"
      rpy="3.1416 0 1.5708" />
    <parent
      link="Link3" />
    <child
      link="Link4" />
    <axis
      xyz="0 0 -1" />
    <limit
      lower="-3.14"
      upper="3.14"
      effort="100"
      velocity="1" />
  </joint>
  <link
    name="Link5">
    <inertial>
      <origin
        xyz="8.31659371565952E-06 -0.00157876424743546 -0.00388136457111554"
        rpy="0 0 0" />
      <mass
        value="0.300359864221293" />
      <inertia
        ixx="0.000245139234644353"
        ixy="-7.28561239566774E-08"
        ixz="2.03267826329419E-08"
        iyy="0.000255934227064357"
        iyz="4.8060068095637E-07"
        izz="0.00023042238037873" />
    </inertial>
    <visual>
      <origin
        xyz="0 0 0"
        rpy="0 0 0" />
      <geometry>
        <mesh
          filename="package://model_config/meshes/Link5.STL" />
      </geometry>
      <material
        name="">
        <color
          rgba="1 1 1 1" />
      </material>
    </visual>
    <collision>
      <origin
        xyz="0 0 0"
        rpy="0 0 0" />
      <geometry>
        <mesh
          filename="package://model_config/meshes/Link5.STL" />
      </geometry>
    </collision>
  </link>
  <joint
    name="Joint5"
    type="revolute">
    <origin
      xyz="0 0.086 0"
      rpy="-1.5708 0 0" />
    <parent
      link="Link4" />
    <child
      link="Link5" />
    <axis
      xyz="0 0 -1" />
    <limit
      lower="-3.14"
      upper="3.14"
      effort="100"
      velocity="1" />
  </joint>
  <link
    name="Link6">
    <inertial>
      <origin
        xyz="0.000177242815501588 -0.000367648782456875 0.0539968712410375"
        rpy="0 0 0" />
      <mass
        value="1.14519625385175" />
      <inertia
        ixx="0.000921548528176975"
        ixy="-1.71472778864732E-08"
        ixz="-2.82009119703302E-07"
        iyy="0.00282722371935467"
        iyz="-1.59907159804116E-07"
        izz="0.00255998892680834" />
    </inertial>
    <visual>
      <origin
        xyz="0 0 0"
        rpy="0 0 0" />
      <geometry>
        <mesh
          filename="package://model_config/meshes/Link6.STL" />
      </geometry>
      <material
        name="">
        <color
          rgba="1 1 1 1" />
      </material>
    </visual>
    <collision>
      <origin
        xyz="0 0 0"
        rpy="0 0 0" />
      <geometry>
        <mesh
          filename="package://model_config/meshes/Link6.STL" />
      </geometry>
    </collision>
  </link>
  <joint
    name="Joint6"
    type="revolute">
    <origin
      xyz="0 -0.0725 0.00036545"
      rpy="1.5708 0 0" />
    <parent
      link="Link5" />
    <child
      link="Link6" />
    <axis
      xyz="0 0 -1" />
    <limit
      lower="-3.14"
      upper="3.14"
      effort="100"
      velocity="1" />
  </joint>
  <link
    name="Link7">
    <inertial>
      <origin
        xyz="-0.0196885659012566 -3.74043091588838E-06 -0.0497629855935276"
        rpy="0 0 0" />
      <mass
        value="0.0797234347218267" />
      <inertia
        ixx="8.11927533946532E-05"
        ixy="1.68372715999088E-08"
        ixz="3.15416807408399E-05"
        iyy="0.000167326452772456"
        iyz="-7.55549771133905E-09"
        izz="9.41026785793423E-05" />
    </inertial>
    <visual>
      <origin
        xyz="0 0 0"
        rpy="0 0 0" />
      <geometry>
        <mesh
          filename="package://model_config/meshes/Link7.STL" />
      </geometry>
      <material
        name="">
        <color
          rgba="1 1 1 1" />
      </material>
    </visual>
    <collision>
      <origin
        xyz="0 0 0"
        rpy="0 0 0" />
      <geometry>
        <mesh
          filename="package://model_config/meshes/Link7.STL" />
      </geometry>
    </collision>
  </link>
  <joint
    name="Joint7"
    type="prismatic">
    <origin
      xyz="-0.099774 -0.00036545 0.2062"
      rpy="0 0 0" />
    <parent
      link="Link6" />
    <child
      link="Link7" />
    <axis
      xyz="1 0 0" />
    <limit
      lower="0"
      upper="0.04"
      effort="100"
      velocity="0.04" />
  </joint>
  <link
    name="Link8">
    <inertial>
      <origin
        xyz="0.019689 3.7404E-06 -0.049763"
        rpy="0 0 0" />
      <mass
        value="0.079723" />
      <inertia
        ixx="8.1193E-05"
        ixy="1.6837E-08"
        ixz="-3.1542E-05"
        iyy="0.00016733"
        iyz="7.5555E-09"
        izz="9.4103E-05" />
    </inertial>
    <visual>
      <origin
        xyz="0 0 0"
        rpy="0 0 0" />
      <geometry>
        <mesh
          filename="package://model_config/meshes/Link8.STL" />
      </geometry>
      <material
        name="">
        <color
          rgba="1 1 1 1" />
      </material>
    </visual>
    <collision>
      <origin
        xyz="0 0 0"
        rpy="0 0 0" />
      <geometry>
        <mesh
          filename="package://model_config/meshes/Link8.STL" />
      </geometry>
    </collision>
  </link>
  <joint
    name="Joint8"
    type="prismatic">
    <origin
      xyz="0.099774 -0.00036545 0.2062"
      rpy="0 0 0" />
    <parent
      link="Link6" />
    <child
      link="Link8" />
    <axis
      xyz="1 0 0" />
    <limit
      lower="-0.04"
      upper="0"
      effort="100"
      velocity="0.04" />
  </joint>
</robot>